<mujoco>
    <compiler inertiafromgeom="true"/>
    <option timestep="0.002" />
    <asset>
        <material name="blue_" rgba="0 0 1 1" />
        <material name="green" rgba="0 1 0 1" />
        <material name="red__" rgba="1 0 0 1" />
        <material name="white" rgba="1 1 1 1" />
    </asset>
    <worldbody>
        <geom type="box" size="2 2 0.1" pos="0 0 -0.15" rgba=".9 0 0 1" />
        <body name="link_4" pos="0.0 0 0." euler="0 0 0">
            <joint name="hinge_3" pos="0 0 0" axis="1 0 0" />
            <geom type="cylinder" size=".02    0.2" pos="0 0.2 0" euler="90 0 0" material="white" />
            <geom type="cylinder" size=".025 .025" pos="0 0 0" euler="0 90 0" material="white" />
            <geom type="cylinder" size=".025 .025" pos="0 0.4 0" euler="0 90 0" material="white" />
        </body>
    </worldbody>
</mujoco>
